<?xml version="1.0" encoding="UTF-8"?>
<testng-results retried="1" ignored="0" total="2" passed="0" failed="1" skipped="0">
  <reporter-output>
  </reporter-output>
  <suite started-at="2025-04-16T17:37:54 IST" name="Suite" finished-at="2025-04-16T17:39:02 IST" duration-ms="67443">
    <groups>
    </groups>
    <test started-at="2025-04-16T17:37:54 IST" name="Negative_ErrorValidationTest" finished-at="2025-04-16T17:39:02 IST" duration-ms="67443">
      <class name="tests.ErrorValidationTest">
        <test-method is-config="true" signature="launchApplication()[pri:0, instance:tests.ErrorValidationTest@6f36c2f0]" started-at="2025-04-16T17:37:54 IST" name="launchApplication" finished-at="2025-04-16T17:38:32 IST" duration-ms="37594" status="PASS">
          <reporter-output>
          </reporter-output>
        </test-method> <!-- launchApplication -->
        <test-method retried="true" signature="IncorrectUserName_SubmitOrder()[pri:0, instance:tests.ErrorValidationTest@6f36c2f0]" started-at="2025-04-16T17:38:32 IST" name="IncorrectUserName_SubmitOrder" finished-at="2025-04-16T17:38:34 IST" duration-ms="2485" status="SKIP">
          <exception class="java.lang.AssertionError">
            <message>
              <![CDATA[expected [Incorrect email password.] but found [Incorrect email or password.]]]>
            </message>
            <full-stacktrace>
              <![CDATA[java.lang.AssertionError: expected [Incorrect email password.] but found [Incorrect email or password.]
at org.testng.Assert.fail(Assert.java:111)
at org.testng.Assert.failNotEquals(Assert.java:1590)
at org.testng.Assert.assertEqualsImpl(Assert.java:150)
at org.testng.Assert.assertEquals(Assert.java:132)
at org.testng.Assert.assertEquals(Assert.java:656)
at org.testng.Assert.assertEquals(Assert.java:666)
at tests.ErrorValidationTest.IncorrectUserName_SubmitOrder(ErrorValidationTest.java:51)
at java.base/jdk.internal.reflect.DirectMethodHandleAccessor.invoke(DirectMethodHandleAccessor.java:103)
at java.base/java.lang.reflect.Method.invoke(Method.java:580)
at org.testng.internal.invokers.MethodInvocationHelper.invokeMethod(MethodInvocationHelper.java:141)
at org.testng.internal.invokers.TestInvoker.invokeMethod(TestInvoker.java:687)
at org.testng.internal.invokers.TestInvoker.invokeTestMethod(TestInvoker.java:230)
at org.testng.internal.invokers.MethodRunner.runInSequence(MethodRunner.java:63)
at org.testng.internal.invokers.TestInvoker$MethodInvocationAgent.invoke(TestInvoker.java:995)
at org.testng.internal.invokers.TestInvoker.invokeTestMethods(TestInvoker.java:203)
at org.testng.internal.invokers.TestMethodWorker.invokeTestMethods(TestMethodWorker.java:154)
at org.testng.internal.invokers.TestMethodWorker.run(TestMethodWorker.java:134)
at java.base/java.util.concurrent.Executors$RunnableAdapter.call(Executors.java:572)
at java.base/java.util.concurrent.FutureTask.run(FutureTask.java:317)
at org.testng.internal.thread.graph.TestNGFutureTask.run(TestNGFutureTask.java:22)
at java.base/java.util.concurrent.ThreadPoolExecutor.runWorker(ThreadPoolExecutor.java:1144)
at java.base/java.util.concurrent.ThreadPoolExecutor$Worker.run(ThreadPoolExecutor.java:642)
at java.base/java.lang.Thread.run(Thread.java:1583)
]]>
            </full-stacktrace>
          </exception> <!-- java.lang.AssertionError -->
          <reporter-output>
          </reporter-output>
        </test-method> <!-- IncorrectUserName_SubmitOrder -->
        <test-method is-config="true" signature="teardown()[pri:0, instance:tests.ErrorValidationTest@6f36c2f0]" started-at="2025-04-16T17:38:34 IST" name="teardown" finished-at="2025-04-16T17:38:43 IST" duration-ms="8399" status="PASS">
          <reporter-output>
          </reporter-output>
        </test-method> <!-- teardown -->
        <test-method is-config="true" signature="launchApplication()[pri:0, instance:tests.ErrorValidationTest@6f36c2f0]" started-at="2025-04-16T17:38:43 IST" name="launchApplication" finished-at="2025-04-16T17:38:52 IST" duration-ms="9334" status="PASS">
          <reporter-output>
          </reporter-output>
        </test-method> <!-- launchApplication -->
        <test-method signature="IncorrectUserName_SubmitOrder()[pri:0, instance:tests.ErrorValidationTest@6f36c2f0]" started-at="2025-04-16T17:38:52 IST" name="IncorrectUserName_SubmitOrder" finished-at="2025-04-16T17:38:53 IST" duration-ms="710" status="FAIL">
          <exception class="java.lang.AssertionError">
            <message>
              <![CDATA[expected [Incorrect email password.] but found [Incorrect email or password.]]]>
            </message>
            <full-stacktrace>
              <![CDATA[java.lang.AssertionError: expected [Incorrect email password.] but found [Incorrect email or password.]
at org.testng.Assert.fail(Assert.java:111)
at org.testng.Assert.failNotEquals(Assert.java:1590)
at org.testng.Assert.assertEqualsImpl(Assert.java:150)
at org.testng.Assert.assertEquals(Assert.java:132)
at org.testng.Assert.assertEquals(Assert.java:656)
at org.testng.Assert.assertEquals(Assert.java:666)
at tests.ErrorValidationTest.IncorrectUserName_SubmitOrder(ErrorValidationTest.java:51)
at java.base/jdk.internal.reflect.DirectMethodHandleAccessor.invoke(DirectMethodHandleAccessor.java:103)
at java.base/java.lang.reflect.Method.invoke(Method.java:580)
at org.testng.internal.invokers.MethodInvocationHelper.invokeMethod(MethodInvocationHelper.java:141)
at org.testng.internal.invokers.TestInvoker.invokeMethod(TestInvoker.java:687)
at org.testng.internal.invokers.TestInvoker.retryFailed(TestInvoker.java:269)
at org.testng.internal.invokers.MethodRunner.runInSequence(MethodRunner.java:76)
at org.testng.internal.invokers.TestInvoker$MethodInvocationAgent.invoke(TestInvoker.java:995)
at org.testng.internal.invokers.TestInvoker.invokeTestMethods(TestInvoker.java:203)
at org.testng.internal.invokers.TestMethodWorker.invokeTestMethods(TestMethodWorker.java:154)
at org.testng.internal.invokers.TestMethodWorker.run(TestMethodWorker.java:134)
at java.base/java.util.concurrent.Executors$RunnableAdapter.call(Executors.java:572)
at java.base/java.util.concurrent.FutureTask.run(FutureTask.java:317)
at org.testng.internal.thread.graph.TestNGFutureTask.run(TestNGFutureTask.java:22)
at java.base/java.util.concurrent.ThreadPoolExecutor.runWorker(ThreadPoolExecutor.java:1144)
at java.base/java.util.concurrent.ThreadPoolExecutor$Worker.run(ThreadPoolExecutor.java:642)
at java.base/java.lang.Thread.run(Thread.java:1583)
]]>
            </full-stacktrace>
          </exception> <!-- java.lang.AssertionError -->
          <reporter-output>
          </reporter-output>
        </test-method> <!-- IncorrectUserName_SubmitOrder -->
        <test-method is-config="true" signature="teardown()[pri:0, instance:tests.ErrorValidationTest@6f36c2f0]" started-at="2025-04-16T17:38:53 IST" name="teardown" finished-at="2025-04-16T17:39:02 IST" duration-ms="8353" status="PASS">
          <reporter-output>
          </reporter-output>
        </test-method> <!-- teardown -->
      </class> <!-- tests.ErrorValidationTest -->
    </test> <!-- Negative_ErrorValidationTest -->
  </suite> <!-- Suite -->
</testng-results>
